Traceback (most recent call last):
  File "/Users/lb788/miniconda3/envs/CfRR/lib/python3.9/site-packages/jupyter_cache/executors/utils.py", line 58, in single_nb_execution
    executenb(
  File "/Users/lb788/miniconda3/envs/CfRR/lib/python3.9/site-packages/nbclient/client.py", line 1314, in execute
    return NotebookClient(nb=nb, resources=resources, km=km, **kwargs).execute()
  File "/Users/lb788/miniconda3/envs/CfRR/lib/python3.9/site-packages/jupyter_core/utils/__init__.py", line 165, in wrapped
    return loop.run_until_complete(inner)
  File "/Users/lb788/miniconda3/envs/CfRR/lib/python3.9/asyncio/base_events.py", line 647, in run_until_complete
    return future.result()
  File "/Users/lb788/miniconda3/envs/CfRR/lib/python3.9/site-packages/nbclient/client.py", line 709, in async_execute
    await self.async_execute_cell(
  File "/Users/lb788/miniconda3/envs/CfRR/lib/python3.9/site-packages/nbclient/client.py", line 1062, in async_execute_cell
    await self._check_raise_for_error(cell, cell_index, exec_reply)
  File "/Users/lb788/miniconda3/envs/CfRR/lib/python3.9/site-packages/nbclient/client.py", line 918, in _check_raise_for_error
    raise CellExecutionError.from_cell_and_msg(cell, exec_reply_content)
nbclient.exceptions.CellExecutionError: An error occurred while executing the following cell:
------------------
``` Julia
Pkg.status()

```
------------------


LoadError: parsing command ` Julia
Pkg.status()

`: special characters "#{}()[]<>|&*?~;" must be quoted in commands
in expression starting at In[1]:1

Stacktrace:
 [1] error(s::String)
   @ Base ./error.jl:35
 [2] shell_parse(str::String, interpolate::Bool; special::String, filename::String)
   @ Base ./shell.jl:122
 [3] shell_parse
   @ ./shell.jl:19 [inlined]
 [4] var"@cmd"(__source__::LineNumberNode, __module__::Module, str::Any)
   @ Base ./cmd.jl:501

